<?xml version="1.0" ?>
<sdf version="1.8">
  <world name="swarm_world">
    <plugin filename="gz-sim-physics-system" name="gz::sim::systems::Physics"/>
    <plugin filename="gz-sim-sensors-system" name="gz::sim::systems::Sensors">
      <render_engine>ogre2</render_engine>
    </plugin>
    <plugin filename="gz-sim-scene-broadcaster-system" name="gz::sim::systems::SceneBroadcaster"/>
    <plugin filename="gz-sim-user-commands-system" name="gz::sim::systems::UserCommands"/>

    <light type="directional" name="sun">
      <cast_shadows>true</cast_shadows>
      <pose>0 0 10 0 0 0</pose>
      <diffuse>1 1 1 1</diffuse>
    </light>

    <model name="ground_plane">
      <static>true</static>
      <link name="link">
        <collision name="collision">
          <geometry><plane><normal>0 0 1</normal></plane></geometry>
        </collision>
        <visual name="visual">
          <geometry><plane><normal>0 0 1</normal><size>100 100</size></plane></geometry>
        </visual>
      </link>
    </model>

    <model name="wall_north">
      <static>true</static>
      <pose>3 0 0.5 0 0 0</pose>
      <link name="link">
        <collision name="collision">
          <geometry><box><size>0.2 4 1</size></box></geometry>
        </collision>
        <visual name="visual">
          <geometry><box><size>0.2 4 1</size></box></geometry>
        </visual>
      </link>
    </model>

    <model name="wall_south">
      <static>true</static>
      <pose>-3 0 0.5 0 0 0</pose>
      <link name="link">
        <collision name="collision">
          <geometry><box><size>0.2 4 1</size></box></geometry>
        </collision>
        <visual name="visual">
          <geometry><box><size>0.2 4 1</size></box></geometry>
        </visual>
      </link>
    </model>

    <model name="wall_east">
      <static>true</static>
      <pose>0 3 0.5 0 0 0</pose>
      <link name="link">
        <collision name="collision">
          <geometry><box><size>4 0.2 1</size></box></geometry>
        </collision>
        <visual name="visual">
          <geometry><box><size>4 0.2 1</size></box></geometry>
        </visual>
      </link>
    </model>

    <model name="wall_west">
      <static>true</static>
      <pose>0 -3 0.5 0 0 0</pose>
      <link name="link">
        <collision name="collision">
          <geometry><box><size>4 0.2 1</size></box></geometry>
        </collision>
        <visual name="visual">
          <geometry><box><size>4 0.2 1</size></box></geometry>
        </visual>
      </link>
    </model>

    <model name="robot">
      <pose>0 0 0.1 0 0 0</pose>

      <plugin filename="gz-sim-diff-drive-system" name="gz::sim::systems::DiffDrive">
        <left_joint>left_wheel_joint</left_joint>
        <right_joint>right_wheel_joint</right_joint>
        <wheel_separation>0.3</wheel_separation>
        <wheel_radius>0.05</wheel_radius>
        <topic>/cmd_vel</topic>
        <odom_topic>/odom</odom_topic>
        <tf_topic>/tf</tf_topic>
        <frame_id>odom</frame_id>
        <child_frame_id>base_link</child_frame_id>
        <odom_publish_frequency>10</odom_publish_frequency>
      </plugin>

      <plugin filename="gz-sim-joint-state-publisher-system" name="gz::sim::systems::JointStatePublisher"/>

      <link name="base_link">
        <inertial>
          <mass>1.0</mass>
          <!-- box 0.3x0.3x0.1: Ixx=Iyy=m/12*(0.09+0.01), Izz=m/12*(0.09+0.09) -->
          <inertia><ixx>0.00833</ixx><ixy>0</ixy><ixz>0</ixz><iyy>0.00833</iyy><iyz>0</iyz><izz>0.015</izz></inertia>
        </inertial>
        <visual name="visual">
          <geometry><box><size>0.3 0.3 0.1</size></box></geometry>
        </visual>
        <collision name="collision">
          <geometry><box><size>0.3 0.3 0.1</size></box></geometry>
        </collision>
      </link>

      <link name="left_wheel">
        <pose>0 0.15 -0.05 1.5707 0 0</pose>
        <inertial>
          <mass>0.1</mass>
          <!-- cylinder r=0.05 h=0.05: Ixx=Izz=m/12*(3r²+h²), Iyy=m/2*r² -->
          <inertia><ixx>0.000083</ixx><ixy>0</ixy><ixz>0</ixz><iyy>0.000125</iyy><iyz>0</iyz><izz>0.000083</izz></inertia>
        </inertial>
        <visual name="visual">
          <geometry><cylinder><radius>0.05</radius><length>0.05</length></cylinder></geometry>
        </visual>
        <collision name="collision">
          <geometry><cylinder><radius>0.05</radius><length>0.05</length></cylinder></geometry>
        </collision>
      </link>

      <link name="right_wheel">
        <pose>0 -0.15 -0.05 1.5707 0 0</pose>
        <inertial>
          <mass>0.1</mass>
          <inertia><ixx>0.000083</ixx><ixy>0</ixy><ixz>0</ixz><iyy>0.000125</iyy><iyz>0</iyz><izz>0.000083</izz></inertia>
        </inertial>
        <visual name="visual">
          <geometry><cylinder><radius>0.05</radius><length>0.05</length></cylinder></geometry>
        </visual>
        <collision name="collision">
          <geometry><cylinder><radius>0.05</radius><length>0.05</length></cylinder></geometry>
        </collision>
      </link>

      <link name="caster_front">
        <pose>0.1 0 -0.08 0 0 0</pose>
        <inertial>
          <mass>0.05</mass>
          <inertia><ixx>0.000004</ixx><ixy>0</ixy><ixz>0</ixz><iyy>0.000004</iyy><iyz>0</iyz><izz>0.000004</izz></inertia>
        </inertial>
        <visual name="visual">
          <geometry><sphere><radius>0.02</radius></sphere></geometry>
        </visual>
        <collision name="collision">
          <geometry><sphere><radius>0.02</radius></sphere></geometry>
          <surface><friction><ode><mu>0</mu><mu2>0</mu2></ode></friction></surface>
        </collision>
      </link>

      <link name="caster_rear">
        <pose>-0.1 0 -0.08 0 0 0</pose>
        <inertial>
          <mass>0.05</mass>
          <inertia><ixx>0.000004</ixx><ixy>0</ixy><ixz>0</ixz><iyy>0.000004</iyy><iyz>0</iyz><izz>0.000004</izz></inertia>
        </inertial>
        <visual name="visual">
          <geometry><sphere><radius>0.02</radius></sphere></geometry>
        </visual>
        <collision name="collision">
          <geometry><sphere><radius>0.02</radius></sphere></geometry>
          <surface><friction><ode><mu>0</mu><mu2>0</mu2></ode></friction></surface>
        </collision>
      </link>

      <joint name="caster_front_joint" type="ball">
        <parent>base_link</parent>
        <child>caster_front</child>
      </joint>

      <joint name="caster_rear_joint" type="ball">
        <parent>base_link</parent>
        <child>caster_rear</child>
      </joint>

      <joint name="left_wheel_joint" type="revolute">
        <parent>base_link</parent>
        <child>left_wheel</child>
        <axis>
          <xyz expressed_in="__model__">0 1 0</xyz>
        </axis>
      </joint>

      <joint name="right_wheel_joint" type="revolute">
        <parent>base_link</parent>
        <child>right_wheel</child>
        <axis>
          <xyz expressed_in="__model__">0 1 0</xyz>
        </axis>
      </joint>

      <link name="lidar_link">
        <pose>0 0 0.1 0 0 0</pose>
        <inertial>
          <mass>0.05</mass>
          <inertia><ixx>0.000021</ixx><ixy>0</ixy><ixz>0</ixz><iyy>0.000021</iyy><iyz>0</iyz><izz>0.000021</izz></inertia>
        </inertial>
        <sensor name="lidar" type="gpu_lidar">
          <topic>/scan</topic>
          <update_rate>10</update_rate>
          <lidar>
            <scan>
              <horizontal>
                <samples>360</samples>
                <resolution>1</resolution>
                <min_angle>-3.14159</min_angle>
                <max_angle>3.14159</max_angle>
              </horizontal>
            </scan>
            <range>
              <min>0.1</min>
              <max>10.0</max>
            </range>
          </lidar>
          <always_on>1</always_on>
          <visualize>true</visualize>
        </sensor>
      </link>

      <joint name="lidar_joint" type="fixed">
        <parent>base_link</parent>
        <child>lidar_link</child>
      </joint>
    </model>
  </world>
</sdf>
